Watching for file changes with StatReloader
Performing system checks...

System check identified no issues (0 silenced).
September 25, 2023 - 06:34:56
Django version 3.2.16, using settings 'django_usang.settings'
Starting development server at http://172.25.0.21:8001/
Quit the server with CONTROL-C.
[25/Sep/2023 06:35:12] "POST /api/v1/token/ HTTP/1.1" 201 483
[25/Sep/2023 06:35:17] "POST /api/v1/search/ HTTP/1.1" 200 475
[25/Sep/2023 06:35:21] "GET /api/v1/count/ HTTP/1.1" 200 43
[25/Sep/2023 06:35:40] "GET /api/v1/count/ HTTP/1.1" 200 43
[25/Sep/2023 06:35:41] "GET /api/v1/count/ HTTP/1.1" 200 43
[25/Sep/2023 06:35:41] "GET /api/v1/count/ HTTP/1.1" 200 43
[25/Sep/2023 06:35:42] "GET /api/v1/count/ HTTP/1.1" 200 43
[25/Sep/2023 06:35:43] "GET /api/v1/count/ HTTP/1.1" 200 43
[25/Sep/2023 06:35:43] "GET /api/v1/count/ HTTP/1.1" 200 43
[25/Sep/2023 06:35:44] "GET /api/v1/count/ HTTP/1.1" 200 43
[25/Sep/2023 06:35:44] "GET /api/v1/count/ HTTP/1.1" 200 43
[25/Sep/2023 07:31:25,720] - Broken pipe from ('172.25.0.150', 50597)

Method Not Allowed: /api/v1/token/
[26/Sep/2023 02:00:43] "GET /api/v1/token/ HTTP/1.1" 405 10446
[26/Sep/2023 02:00:43] "GET /static/rest_framework/css/bootstrap-tweaks.css HTTP/1.1" 200 3385
[26/Sep/2023 02:00:43] "GET /static/rest_framework/css/prettify.css HTTP/1.1" 200 817
[26/Sep/2023 02:00:43] "GET /static/rest_framework/css/default.css HTTP/1.1" 200 1152
[26/Sep/2023 02:00:43] "GET /static/rest_framework/js/csrf.js HTTP/1.1" 200 1719
[26/Sep/2023 02:00:43] "GET /static/rest_framework/css/bootstrap.min.css HTTP/1.1" 200 121457
[26/Sep/2023 02:00:43] "GET /static/rest_framework/js/ajax-form.js HTTP/1.1" 200 3597
[26/Sep/2023 02:00:43] "GET /static/rest_framework/js/jquery-3.5.1.min.js HTTP/1.1" 200 89476
[26/Sep/2023 02:00:43] "GET /static/rest_framework/js/prettify-min.js HTTP/1.1" 200 13632
[26/Sep/2023 02:00:43] "GET /static/rest_framework/js/default.js HTTP/1.1" 200 1268
[26/Sep/2023 02:00:43] "GET /static/rest_framework/js/bootstrap.min.js HTTP/1.1" 200 39680
[26/Sep/2023 02:00:43] "GET /static/rest_framework/img/grid.png HTTP/1.1" 200 1458
Not Found: /favicon.ico
[26/Sep/2023 02:00:43] "GET /favicon.ico HTTP/1.1" 404 2225
Unauthorized: /api/v1/token/
[26/Sep/2023 02:01:14] "POST /api/v1/token/ HTTP/1.1" 401 10422
[26/Sep/2023 02:01:24] "POST /api/v1/token/ HTTP/1.1" 201 10895
Unauthorized: /api/v1/search/
[26/Sep/2023 02:06:35] "GET /api/v1/search/ HTTP/1.1" 401 8614
Unauthorized: /api/v1/search/
[26/Sep/2023 06:17:07] "GET /api/v1/search/ HTTP/1.1" 401 8614
Unauthorized: /api/v1/search/
[26/Sep/2023 06:20:42] "POST /api/v1/search/ HTTP/1.1" 401 183
Unauthorized: /api/v1/search/
[26/Sep/2023 06:29:48] "POST /api/v1/search/ HTTP/1.1" 401 58
[26/Sep/2023 06:31:55] "POST /api/v1/token/ HTTP/1.1" 201 483
[26/Sep/2023 06:33:53] "POST /api/v1/search/ HTTP/1.1" 200 475
[26/Sep/2023 06:58:04,417] - Broken pipe from ('172.25.0.150', 57086)

[26/Sep/2023 07:02:23] "POST /api/v1/token/ HTTP/1.1" 201 483
[26/Sep/2023 07:04:43] "POST /api/v1/search/ HTTP/1.1" 200 475
Watching for file changes with StatReloader
Performing system checks...

System check identified no issues (0 silenced).
October 04, 2023 - 05:58:41
Django version 3.2.16, using settings 'django_usang.settings'
Starting development server at http://172.25.0.21:8001/
Quit the server with CONTROL-C.
[05/Oct/2023 04:53:23] "POST /api/v1/token/ HTTP/1.1" 201 483
[05/Oct/2023 04:53:39] "POST /api/v1/search/ HTTP/1.1" 200 796
[05/Oct/2023 04:53:52] "POST /api/v1/search/ HTTP/1.1" 200 80140
[05/Oct/2023 04:55:01] "POST /api/v1/search/ HTTP/1.1" 200 3127
[05/Oct/2023 04:56:38] "POST /api/v1/search/ HTTP/1.1" 200 31
[05/Oct/2023 04:56:43] "POST /api/v1/search/ HTTP/1.1" 200 31
[05/Oct/2023 04:56:46] "POST /api/v1/search/ HTTP/1.1" 200 31
[05/Oct/2023 04:56:50] "POST /api/v1/search/ HTTP/1.1" 200 911
[05/Oct/2023 05:01:26] "POST /api/v1/token/ HTTP/1.1" 201 483
[05/Oct/2023 05:01:39] "POST /api/v1/search/ HTTP/1.1" 200 31
[05/Oct/2023 05:01:46] "POST /api/v1/search/ HTTP/1.1" 200 80140
[05/Oct/2023 05:01:53] "GET /api/v1/count/ HTTP/1.1" 200 43
/home/manager/django_usang/api/views.py changed, reloading.
Watching for file changes with StatReloader
Performing system checks...

System check identified no issues (0 silenced).
October 05, 2023 - 06:59:53
Django version 3.2.16, using settings 'django_usang.settings'
Starting development server at http://172.25.0.21:8001/
Quit the server with CONTROL-C.
/home/manager/django_usang/api/urls.py changed, reloading.
Watching for file changes with StatReloader
Performing system checks...

Exception in thread django-main-thread:
Traceback (most recent call last):
  File "/home/manager/anaconda3/envs/venv/lib/python3.8/threading.py", line 932, in _bootstrap_inner
    self.run()
  File "/home/manager/anaconda3/envs/venv/lib/python3.8/threading.py", line 870, in run
    self._target(*self._args, **self._kwargs)
  File "/home/manager/.local/lib/python3.8/site-packages/django/utils/autoreload.py", line 64, in wrapper
    fn(*args, **kwargs)
  File "/home/manager/.local/lib/python3.8/site-packages/django/core/management/commands/runserver.py", line 118, in inner_run
    self.check(display_num_errors=True)
  File "/home/manager/.local/lib/python3.8/site-packages/django/core/management/base.py", line 419, in check
    all_issues = checks.run_checks(
  File "/home/manager/.local/lib/python3.8/site-packages/django/core/checks/registry.py", line 76, in run_checks
    new_errors = check(app_configs=app_configs, databases=databases)
  File "/home/manager/.local/lib/python3.8/site-packages/django/core/checks/urls.py", line 13, in check_url_config
    return check_resolver(resolver)
  File "/home/manager/.local/lib/python3.8/site-packages/django/core/checks/urls.py", line 23, in check_resolver
    return check_method()
  File "/home/manager/.local/lib/python3.8/site-packages/django/urls/resolvers.py", line 416, in check
    for pattern in self.url_patterns:
  File "/home/manager/.local/lib/python3.8/site-packages/django/utils/functional.py", line 48, in __get__
    res = instance.__dict__[self.name] = self.func(instance)
  File "/home/manager/.local/lib/python3.8/site-packages/django/urls/resolvers.py", line 602, in url_patterns
    patterns = getattr(self.urlconf_module, "urlpatterns", self.urlconf_module)
  File "/home/manager/.local/lib/python3.8/site-packages/django/utils/functional.py", line 48, in __get__
    res = instance.__dict__[self.name] = self.func(instance)
  File "/home/manager/.local/lib/python3.8/site-packages/django/urls/resolvers.py", line 595, in urlconf_module
    return import_module(self.urlconf_name)
  File "/home/manager/anaconda3/envs/venv/lib/python3.8/importlib/__init__.py", line 127, in import_module
    return _bootstrap._gcd_import(name[level:], package, level)
  File "<frozen importlib._bootstrap>", line 1014, in _gcd_import
  File "<frozen importlib._bootstrap>", line 991, in _find_and_load
  File "<frozen importlib._bootstrap>", line 975, in _find_and_load_unlocked
  File "<frozen importlib._bootstrap>", line 671, in _load_unlocked
  File "<frozen importlib._bootstrap_external>", line 843, in exec_module
  File "<frozen importlib._bootstrap>", line 219, in _call_with_frames_removed
  File "/home/manager/django_usang/django_usang/urls.py", line 22, in <module>
    path('api/v1/', include('api.urls')),
  File "/home/manager/.local/lib/python3.8/site-packages/django/urls/conf.py", line 34, in include
    urlconf_module = import_module(urlconf_module)
  File "/home/manager/anaconda3/envs/venv/lib/python3.8/importlib/__init__.py", line 127, in import_module
    return _bootstrap._gcd_import(name[level:], package, level)
  File "<frozen importlib._bootstrap>", line 1014, in _gcd_import
  File "<frozen importlib._bootstrap>", line 991, in _find_and_load
  File "<frozen importlib._bootstrap>", line 975, in _find_and_load_unlocked
  File "<frozen importlib._bootstrap>", line 671, in _load_unlocked
  File "<frozen importlib._bootstrap_external>", line 843, in exec_module
  File "<frozen importlib._bootstrap>", line 219, in _call_with_frames_removed
  File "/home/manager/django_usang/api/urls.py", line 8, in <module>
    path('download/', DownloadView.as_view(), name='download'),
NameError: name 'DownloadView' is not defined
/home/manager/django_usang/api/views.py changed, reloading.
Watching for file changes with StatReloader
Performing system checks...

Exception in thread django-main-thread:
Traceback (most recent call last):
  File "/home/manager/anaconda3/envs/venv/lib/python3.8/threading.py", line 932, in _bootstrap_inner
    self.run()
  File "/home/manager/anaconda3/envs/venv/lib/python3.8/threading.py", line 870, in run
    self._target(*self._args, **self._kwargs)
  File "/home/manager/.local/lib/python3.8/site-packages/django/utils/autoreload.py", line 64, in wrapper
    fn(*args, **kwargs)
  File "/home/manager/.local/lib/python3.8/site-packages/django/core/management/commands/runserver.py", line 118, in inner_run
    self.check(display_num_errors=True)
  File "/home/manager/.local/lib/python3.8/site-packages/django/core/management/base.py", line 419, in check
    all_issues = checks.run_checks(
  File "/home/manager/.local/lib/python3.8/site-packages/django/core/checks/registry.py", line 76, in run_checks
    new_errors = check(app_configs=app_configs, databases=databases)
  File "/home/manager/.local/lib/python3.8/site-packages/django/core/checks/urls.py", line 13, in check_url_config
    return check_resolver(resolver)
  File "/home/manager/.local/lib/python3.8/site-packages/django/core/checks/urls.py", line 23, in check_resolver
    return check_method()
  File "/home/manager/.local/lib/python3.8/site-packages/django/urls/resolvers.py", line 416, in check
    for pattern in self.url_patterns:
  File "/home/manager/.local/lib/python3.8/site-packages/django/utils/functional.py", line 48, in __get__
    res = instance.__dict__[self.name] = self.func(instance)
  File "/home/manager/.local/lib/python3.8/site-packages/django/urls/resolvers.py", line 602, in url_patterns
    patterns = getattr(self.urlconf_module, "urlpatterns", self.urlconf_module)
  File "/home/manager/.local/lib/python3.8/site-packages/django/utils/functional.py", line 48, in __get__
    res = instance.__dict__[self.name] = self.func(instance)
  File "/home/manager/.local/lib/python3.8/site-packages/django/urls/resolvers.py", line 595, in urlconf_module
    return import_module(self.urlconf_name)
  File "/home/manager/anaconda3/envs/venv/lib/python3.8/importlib/__init__.py", line 127, in import_module
    return _bootstrap._gcd_import(name[level:], package, level)
  File "<frozen importlib._bootstrap>", line 1014, in _gcd_import
  File "<frozen importlib._bootstrap>", line 991, in _find_and_load
  File "<frozen importlib._bootstrap>", line 975, in _find_and_load_unlocked
  File "<frozen importlib._bootstrap>", line 671, in _load_unlocked
  File "<frozen importlib._bootstrap_external>", line 843, in exec_module
  File "<frozen importlib._bootstrap>", line 219, in _call_with_frames_removed
  File "/home/manager/django_usang/django_usang/urls.py", line 22, in <module>
    path('api/v1/', include('api.urls')),
  File "/home/manager/.local/lib/python3.8/site-packages/django/urls/conf.py", line 34, in include
    urlconf_module = import_module(urlconf_module)
  File "/home/manager/anaconda3/envs/venv/lib/python3.8/importlib/__init__.py", line 127, in import_module
    return _bootstrap._gcd_import(name[level:], package, level)
  File "<frozen importlib._bootstrap>", line 1014, in _gcd_import
  File "<frozen importlib._bootstrap>", line 991, in _find_and_load
  File "<frozen importlib._bootstrap>", line 975, in _find_and_load_unlocked
  File "<frozen importlib._bootstrap>", line 671, in _load_unlocked
  File "<frozen importlib._bootstrap_external>", line 843, in exec_module
  File "<frozen importlib._bootstrap>", line 219, in _call_with_frames_removed
  File "/home/manager/django_usang/api/urls.py", line 8, in <module>
    path('download/', DownloadView.as_view(), name='download'),
NameError: name 'DownloadView' is not defined
